<?xml version="1.0"?>
<!-- =================================================================================== -->
<!-- |    This document was autogenerated by xacro from lula_kuka_allegro.urdf.xacro   | -->
<!-- |    EDITING THIS FILE BY HAND IS NOT RECOMMENDED                                 | -->
<!-- =================================================================================== -->
<robot name="kuka_allegro" xmlns:xacro="http://www.ros.org/wiki/xacro">
  <!-- MATERIALS -->
  <!-- SOURCE:
  https://github.com/IFL-CAMP/iiwa_stack/blob/master/iiwa_description/urdf/materials.xacro-->
  <material name="Black">
    <color rgba="0.0 0.0 0.0 1.0" />
  </material>

  <material name="Blue">
    <color rgba="0.0 0.0 0.8 1.0" />
  </material>

  <material name="Green">
    <color rgba="0.0 0.8 0.0 1.0" />
  </material>

  <material name="Grey">
    <color rgba="0.4 0.4 0.4 1.0" />
  </material>

  <material name="Orange">
    <color rgba="1.0 0.4235 0.0392 1.0" />
  </material>

  <material name="Brown">
    <color rgba="0.8706 0.8118 0.7647 1.0" />
  </material>

  <material name="Red">
    <color rgba="0.8 0.0 0.0 1.0" />
  </material>

  <material name="White">
    <color rgba="1.0 1.0 1.0 1.0" />
  </material>

  <!-- KUKA IIWA 14 -->
  <!-- SOURCE: https://github.com/IFL-CAMP/iiwa_stack/blob/master/iiwa_description/urdf/iiwa14.xacro -->
  <link name="iiwa14_link_0">
    <inertial>
      <origin xyz="-0.1 0 0.07" rpy="0 0 0" />
      <mass value="5" />
      <inertia ixx="0.05" ixy="0" ixz="0" iyy="0.06" iyz="0" izz="0.03" />
    </inertial>

    <visual>
      <origin xyz="0 0 0" rpy="0 0 0" />
      <geometry>
        <mesh filename="new_iiwa14_meshes/visual/link_0.stl" />
      </geometry>
      <material name="Grey" />
    </visual>

    <collision>
      <origin xyz="0 0 0" rpy="0 0 0" />
      <geometry>
        <mesh filename="new_iiwa14_meshes/collision/link_0.stl" />
      </geometry>
      <material name="Grey" />
    </collision>

    <self_collision_checking>
      <origin xyz="0 0 0" rpy="0 0 0" />
      <geometry>
        <capsule radius="0.15" length="0.25" />
      </geometry>
    </self_collision_checking>
  </link>

  <!-- joint between link_0 and link_1 -->
  <joint name="iiwa14_joint_1" type="revolute">
    <parent link="iiwa14_link_0" />
    <child link="iiwa14_link_1" />
    <origin xyz="0 0 0.1575" rpy="0 0 0" />
    <axis xyz="0 0 1" />
    <limit lower="-2.96705972839" upper="2.96705972839"
      effort="300" velocity="10" />
    <safety_controller soft_lower_limit="-2.93215314335"
      soft_upper_limit="2.93215314335"
      k_position="100"
      k_velocity="2" />
    <dynamics damping="0.5" />
  </joint>

  <link name="iiwa14_link_1">
    <inertial>
      <origin xyz="0 -0.03 0.12" rpy="0 0 0" />
      <mass value="4" />
      <inertia ixx="0.1" ixy="0" ixz="0" iyy="0.09" iyz="0" izz="0.02" />
    </inertial>

    <visual>
      <origin xyz="0 0 0" rpy="0 0 0" />
      <geometry>
        <mesh filename="new_iiwa14_meshes/visual/link_1.stl" />
      </geometry>
      <material name="Orange" />
    </visual>

    <collision>
      <origin xyz="0 0 0" rpy="0 0 0" />
      <geometry>
        <mesh filename="new_iiwa14_meshes/collision/link_1.stl" />
      </geometry>
      <material name="Orange" />
    </collision>
  </link>

  <!-- joint between link_1 and link_2 -->
  <joint name="iiwa14_joint_2" type="revolute">
    <parent link="iiwa14_link_1" />
    <child link="iiwa14_link_2" />
    <origin xyz="0 0 0.2025" rpy="1.57079632679   0 3.14159265359" />
    <axis xyz="0 0 1" />
    <limit lower="-2.09439510239" upper="2.09439510239"
      effort="300" velocity="10" />
    <safety_controller soft_lower_limit="-2.05948851735"
      soft_upper_limit="2.05948851735"
      k_position="100"
      k_velocity="2" />
    <dynamics damping="0.5" />
  </joint>

  <link name="iiwa14_link_2">
    <inertial>
      <origin xyz="0.0003 0.059 0.042" rpy="0 0 0" />
      <mass value="4" />
      <inertia ixx="0.05" ixy="0" ixz="0" iyy="0.018" iyz="0" izz="0.044" />
    </inertial>

    <visual>
      <origin xyz="0 0 0" rpy="0 0 0" />
      <geometry>
        <mesh filename="new_iiwa14_meshes/visual/link_2.stl" />
      </geometry>
      <material name="Orange" />
    </visual>

    <collision>
      <origin xyz="0 0 0" rpy="0 0 0" />
      <geometry>
        <mesh filename="new_iiwa14_meshes/collision/link_2.stl" />
      </geometry>
      <material name="Orange" />
    </collision>
  </link>

  <!-- joint between link_2 and link_3 -->
  <joint name="iiwa14_joint_3" type="revolute">
    <parent link="iiwa14_link_2" />
    <child link="iiwa14_link_3" />
    <origin xyz="0 0.2045 0" rpy="1.57079632679 0 3.14159265359" />
    <axis xyz="0 0 1" />
    <limit lower="-2.96705972839" upper="2.96705972839"
      effort="300" velocity="10" />
    <safety_controller soft_lower_limit="-2.93215314335"
      soft_upper_limit="2.93215314335"
      k_position="100"
      k_velocity="2" />
    <dynamics damping="0.5" />
  </joint>

  <link name="iiwa14_link_3">
    <inertial>
      <origin xyz="0 0.03 0.13" rpy="0 0 0" />
      <mass value="3" />
      <inertia ixx="0.08" ixy="0" ixz="0" iyy="0.075" iyz="0" izz="0.01" />
    </inertial>

    <visual>
      <origin xyz="0 0 0" rpy="0 0 0" />
      <geometry>
        <mesh filename="new_iiwa14_meshes/visual/link_3.stl" />
      </geometry>
      <material name="Orange" />
    </visual>

    <collision>
      <origin xyz="0 0 0" rpy="0 0 0" />
      <geometry>
        <mesh filename="new_iiwa14_meshes/collision/link_3.stl" />
      </geometry>
      <material name="Orange" />
    </collision>
  </link>

  <!-- joint between link_3 and link_4 -->
  <joint name="iiwa14_joint_4" type="revolute">
    <parent link="iiwa14_link_3" />
    <child link="iiwa14_link_4" />
    <origin xyz="0 0 0.2155" rpy="1.57079632679 0 0" />
    <axis xyz="0 0 1" />
    <limit lower="-2.09439510239" upper="2.09439510239"
      effort="300" velocity="10" />
    <safety_controller soft_lower_limit="-2.05948851735"
      soft_upper_limit="2.05948851735"
      k_position="100"
      k_velocity="2" />
    <dynamics damping="0.5" />
  </joint>

  <link name="iiwa14_link_4">
    <inertial>
      <origin xyz="0 0.067 0.034" rpy="0 0 0" />
      <mass value="2.7" />
      <inertia ixx="0.03" ixy="0" ixz="0" iyy="0.01" iyz="0" izz="0.029" />
    </inertial>

    <visual>
      <origin xyz="0 0 0" rpy="0 0 0" />
      <geometry>
        <mesh filename="new_iiwa14_meshes/visual/link_4.stl" />
      </geometry>
      <material name="Orange" />
    </visual>

    <collision>
      <origin xyz="0 0 0" rpy="0 0 0" />
      <geometry>
        <mesh filename="new_iiwa14_meshes/collision/link_4.stl" />
      </geometry>
      <material name="Orange" />
    </collision>
  </link>

  <!-- joint between link_4 and link_5 -->
  <joint name="iiwa14_joint_5" type="revolute">
    <parent link="iiwa14_link_4" />
    <child link="iiwa14_link_5" />
    <origin xyz="0 0.1845 0" rpy="-1.57079632679 3.14159265359 0" />
    <axis xyz="0 0 1" />
    <limit lower="-2.96705972839" upper="2.96705972839"
      effort="300" velocity="10" />
    <safety_controller soft_lower_limit="-2.93215314335"
      soft_upper_limit="2.93215314335"
      k_position="100"
      k_velocity="2" />
    <dynamics damping="0.5" />
  </joint>

  <link name="iiwa14_link_5">
    <inertial>
      <origin xyz="0.0001 0.021 0.076" rpy="0 0 0" />
      <mass value="1.7" />
      <inertia ixx="0.02" ixy="0" ixz="0" iyy="0.018" iyz="0" izz="0.005" />
    </inertial>

    <visual>
      <origin xyz="0 0 0" rpy="0 0 0" />
      <geometry>
        <mesh filename="new_iiwa14_meshes/visual/link_5.stl" />
      </geometry>
      <material name="Orange" />
    </visual>

    <collision>
      <origin xyz="0 0 0" rpy="0 0 0" />
      <geometry>
        <mesh filename="new_iiwa14_meshes/collision/link_5.stl" />
      </geometry>
      <material name="Orange" />
    </collision>
  </link>

  <!-- joint between link_5 and link_6 -->
  <joint name="iiwa14_joint_6" type="revolute">
    <parent link="iiwa14_link_5" />
    <child link="iiwa14_link_6" />
    <origin xyz="0 0 0.2155" rpy="1.57079632679 0 0" />
    <axis xyz="0 0 1" />
    <limit lower="-2.09439510239" upper="2.09439510239"
      effort="300" velocity="10" />
    <safety_controller soft_lower_limit="-2.05948851735"
      soft_upper_limit="2.05948851735"
      k_position="100"
      k_velocity="2" />
    <dynamics damping="0.5" />
  </joint>

  <link name="iiwa14_link_6">
    <inertial>
      <origin xyz="0 0.0006 0.0004" rpy="0 0 0" />
      <mass value="1.8" />
      <inertia ixx="0.005" ixy="0" ixz="0" iyy="0.0036" iyz="0" izz="0.0047" />
    </inertial>

    <visual>
      <origin xyz="0 0 0" rpy="0 0 0" />
      <geometry>
        <mesh filename="new_iiwa14_meshes/visual/link_6.stl" />
      </geometry>
      <material name="Orange" />
    </visual>

    <collision>
      <origin xyz="0 0 0" rpy="0 0 0" />
      <geometry>
        <mesh filename="new_iiwa14_meshes/collision/link_6.stl" />
      </geometry>
      <material name="Orange" />
    </collision>
  </link>

  <!-- joint between link_6 and link_7 -->
  <joint name="iiwa14_joint_7" type="revolute">
    <parent link="iiwa14_link_6" />
    <child link="iiwa14_link_7" />
    <origin xyz="0 0.081 0" rpy="-1.57079632679 3.14159265359 0" />
    <axis xyz="0 0 1" />
    <limit lower="-3.05432619099" upper="3.05432619099"
      effort="300" velocity="10" />
    <safety_controller soft_lower_limit="-3.01941960595"
      soft_upper_limit="3.01941960595"
      k_position="100"
      k_velocity="2" />
    <dynamics damping="0.5" />
  </joint>

  <link name="iiwa14_link_7">
    <inertial>
      <origin xyz="0 0 0.02" rpy="0 0 0" />
      <mass value="0.3" />
      <inertia ixx="0.001" ixy="0" ixz="0" iyy="0.001" iyz="0" izz="0.001" />
    </inertial>

    <visual>
      <origin xyz="0 0 0" rpy="0 0 0" />
      <geometry>
        <mesh filename="new_iiwa14_meshes/visual/link_7.stl" />
      </geometry>
      <material name="Grey" />
    </visual>

    <collision>
      <origin xyz="0 0 0" rpy="0 0 0" />
      <geometry>
        <mesh filename="new_iiwa14_meshes/collision/link_7.stl" />
      </geometry>
      <material name="Grey" />
    </collision>
  </link>

  <joint name="iiwa14_joint_ee" type="fixed">
    <parent link="iiwa14_link_7" />
    <child link="iiwa14_link_ee" />
    <origin xyz="0 0 0.045" rpy="0 0 0" />
  </joint>

  <link name="iiwa14_link_ee">
  </link>

  <!-- Allegro custom mount -->
  <joint name="iiwa14_allegro_custom_mount" type="fixed">
    <parent link="iiwa14_link_ee" />
    <child link="allegro_custom_mount" />
    <!-- <origin xyz="0.02813 0.03938 0.006" rpy="0 0 0" /> -->
    <!-- <origin xyz="0.0562605 0.0128878 0.006" rpy="0 0 0" /> -->
    <origin xyz="-0.0128878 0.0562605 0.006" rpy="0 0 1.57" />
  </joint>

  <link name="allegro_custom_mount">
    <inertial>
      <!-- Estimate mass of this mount with 0.1 x 0.1 x 0.035 of PLA 1.25g/cm^3 -->
      <origin xyz="0 0 0" rpy="0 0 0" />
      <mass value="0.4375" />
      <inertia ixx="0.000394" ixy="0" ixz="0" iyy="0.000394" iyz="0" izz="0.000729" />
    </inertial>

    <visual>
      <origin xyz="0 0 0" rpy="0 0 0" />
      <geometry>
        <mesh filename="new_mount_meshes/allegro-right-to-kuka-mount.stl" scale="0.001 0.001 0.001" />
      </geometry>
      <material name="white">
        <color rgba=".9 .9 .9 1" />
      </material>
    </visual>

    <collision>
      <origin xyz="0 0 0" rpy="0 0 0" />
      <geometry>
        <mesh filename="new_mount_meshes/allegro-right-to-kuka-mount.stl" scale="0.001 0.001 0.001" />
      </geometry>
    </collision>

  </link>

  <joint name="iiwa14_allegro_custom_mount2" type="fixed">
    <parent link="iiwa14_link_ee" />
    <child link="allegro_custom_mount2" />
    <origin xyz="0 0 0.006" rpy="3.14 0 -1.57" />
  </joint>

  <link name="allegro_custom_mount2">
    <visual>
      <origin xyz="0 0 0" rpy="0 0 0" />
      <geometry>
        <mesh filename="new_mount_meshes/kuka_gopro_v2.stl" scale="0.001 0.001 0.001" />
      </geometry>
      <material name="white">
        <color rgba=".9 .9 .9 1" />
      </material>
    </visual>

    <collision>
      <origin xyz="0 0 0" rpy="0 0 0" />
      <geometry>
        <mesh filename="new_mount_meshes/kuka_gopro_v2.stl" scale="0.001 0.001 0.001" />
      </geometry>
    </collision>

  </link>


  <!--Sphere
  link-->
  <link name="iiwa14_link_2_sphere2">
  </link>

  <joint name="iiwa14_joint_2_sphere2" type="fixed">
    <parent link="iiwa14_link_2" />
    <child link="iiwa14_link_2_sphere2" />
    <origin rpy="0 0 0" xyz="0 0.15 0" />
    <axis xyz="0 0 1" />
  </joint>

  <!--Sphere
  link-->
  <link name="iiwa14_link_2_sphere3">
  </link>

  <joint name="iiwa14_joint_2_sphere3" type="fixed">
    <parent link="iiwa14_link_2" />
    <child link="iiwa14_link_2_sphere3" />
    <origin rpy="0 0 0" xyz="0 0.25 0" />
    <axis xyz="0 0 1" />
  </joint>

  <!--Sphere
  link-->
  <link name="iiwa14_link_2_sphere4">
  </link>

  <joint name="iiwa14_joint_2_sphere4" type="fixed">
    <parent link="iiwa14_link_2" />
    <child link="iiwa14_link_2_sphere4" />
    <origin rpy="0 0 0" xyz="0 -0.25 0" />
    <axis xyz="0 0 1" />
  </joint>

  <!--Sphere
  link-->
  <link name="iiwa14_link_4_sphere2">
  </link>

  <joint name="iiwa14_joint_4_sphere2" type="fixed">
    <parent link="iiwa14_link_4" />
    <child link="iiwa14_link_4_sphere2" />
    <origin rpy="0 0 0" xyz="0 0.15 0" />
    <axis xyz="0 0 1" />
  </joint>

  <!--Sphere
  link-->
  <link name="iiwa14_link_4_sphere3">
  </link>

  <joint name="iiwa14_joint_4_sphere3" type="fixed">
    <parent link="iiwa14_link_4" />
    <child link="iiwa14_link_4_sphere3" />
    <origin rpy="0 0 0" xyz="0 0.25 0" />
    <axis xyz="0 0 1" />
  </joint>

  <!--Sphere
  link-->
  <link name="iiwa14_link_6_sphere2">
  </link>

  <joint name="iiwa14_joint_6_sphere2" type="fixed">
    <parent link="iiwa14_link_6" />
    <child link="iiwa14_link_6_sphere2" />
    <origin rpy="0 0 0" xyz="0 0 0" />
    <axis xyz="0 0 1" />
  </joint>

  <!--Sphere
  link-->
  <link name="iiwa14_link_6_sphere3">
  </link>

  <joint name="iiwa14_joint_6_sphere3" type="fixed">
    <parent link="iiwa14_link_6" />
    <child link="iiwa14_link_6_sphere3" />
    <origin rpy="0 0 0" xyz="0 0 -0.05" />
    <axis xyz="0 0 1" />
  </joint>

  <!-- Load Gazebo lib and set the robot namespace -->
  <!-- <gazebo>
      <plugin name="gazebo_ros_control" filename="libgazebo_ros_control.so">
        <robotNamespace>/${robot_name}</robotNamespace>
      </plugin>
    </gazebo> -->
  <!-- Link0 -->
  <gazebo reference="iiwa14_link_0">
    <material>Gazebo/Orange</material>
    <mu1>0.2</mu1>
    <mu2>0.2</mu2>
  </gazebo>
  <!-- Link1 -->
  <gazebo reference="iiwa14_link_1">
    <material>Gazebo/Orange</material>
    <mu1>0.2</mu1>
    <mu2>0.2</mu2>
  </gazebo>
  <!-- Link2 -->
  <gazebo reference="iiwa14_link_2">
    <material>Gazebo/Orange</material>
    <mu1>0.2</mu1>
    <mu2>0.2</mu2>
  </gazebo>
  <!-- Link3 -->
  <gazebo reference="iiwa14_link_3">
    <material>Gazebo/Orange</material>
    <mu1>0.2</mu1>
    <mu2>0.2</mu2>
  </gazebo>
  <!-- Link4 -->
  <gazebo reference="iiwa14_link_4">
    <material>Gazebo/Orange</material>
    <mu1>0.2</mu1>
    <mu2>0.2</mu2>
  </gazebo>
  <!-- Link5 -->
  <gazebo reference="iiwa14_link_5">
    <material>Gazebo/Orange</material>
    <mu1>0.2</mu1>
    <mu2>0.2</mu2>
  </gazebo>
  <!-- Link6 -->
  <gazebo reference="iiwa14_link_6">
    <material>Gazebo/Orange</material>
    <mu1>0.2</mu1>
    <mu2>0.2</mu2>
  </gazebo>
  <!-- Link7 -->
  <gazebo reference="iiwa14_link_7">
    <material>Gazebo/Orange</material>
    <mu1>0.2</mu1>
    <mu2>0.2</mu2>
  </gazebo>
  <transmission name="iiwa14_tran_1">
    <robotNamespace>/iiwa14</robotNamespace>
    <type>transmission_interface/SimpleTransmission</type>
    <joint name="iiwa14_joint_1">
      <hardwareInterface>PositionJointInterface</hardwareInterface>
    </joint>
    <actuator name="iiwa14_motor_1">
      <hardwareInterface>PositionJointInterface</hardwareInterface>
      <mechanicalReduction>1</mechanicalReduction>
    </actuator>
  </transmission>
  <transmission name="iiwa14_tran_2">
    <robotNamespace>/iiwa14</robotNamespace>
    <type>transmission_interface/SimpleTransmission</type>
    <joint name="iiwa14_joint_2">
      <hardwareInterface>PositionJointInterface</hardwareInterface>
    </joint>
    <actuator name="iiwa14_motor_2">
      <hardwareInterface>PositionJointInterface</hardwareInterface>
      <mechanicalReduction>1</mechanicalReduction>
    </actuator>
  </transmission>
  <transmission name="iiwa14_tran_3">
    <robotNamespace>/iiwa14</robotNamespace>
    <type>transmission_interface/SimpleTransmission</type>
    <joint name="iiwa14_joint_3">
      <hardwareInterface>PositionJointInterface</hardwareInterface>
    </joint>
    <actuator name="iiwa14_motor_3">
      <hardwareInterface>PositionJointInterface</hardwareInterface>
      <mechanicalReduction>1</mechanicalReduction>
    </actuator>
  </transmission>
  <transmission name="iiwa14_tran_4">
    <robotNamespace>/iiwa14</robotNamespace>
    <type>transmission_interface/SimpleTransmission</type>
    <joint name="iiwa14_joint_4">
      <hardwareInterface>PositionJointInterface</hardwareInterface>
    </joint>
    <actuator name="iiwa14_motor_4">
      <hardwareInterface>PositionJointInterface</hardwareInterface>
      <mechanicalReduction>1</mechanicalReduction>
    </actuator>
  </transmission>
  <transmission name="iiwa14_tran_5">
    <robotNamespace>/iiwa14</robotNamespace>
    <type>transmission_interface/SimpleTransmission</type>
    <joint name="iiwa14_joint_5">
      <hardwareInterface>PositionJointInterface</hardwareInterface>
    </joint>
    <actuator name="iiwa14_motor_5">
      <hardwareInterface>PositionJointInterface</hardwareInterface>
      <mechanicalReduction>1</mechanicalReduction>
    </actuator>
  </transmission>
  <transmission name="iiwa14_tran_6">
    <robotNamespace>/iiwa14</robotNamespace>
    <type>transmission_interface/SimpleTransmission</type>
    <joint name="iiwa14_joint_6">
      <hardwareInterface>PositionJointInterface</hardwareInterface>
    </joint>
    <actuator name="iiwa14_motor_6">
      <hardwareInterface>PositionJointInterface</hardwareInterface>
      <mechanicalReduction>1</mechanicalReduction>
    </actuator>
  </transmission>
  <transmission name="iiwa14_tran_7">
    <robotNamespace>/iiwa14</robotNamespace>
    <type>transmission_interface/SimpleTransmission</type>
    <joint name="iiwa14_joint_7">
      <hardwareInterface>PositionJointInterface</hardwareInterface>
    </joint>
    <actuator name="iiwa14_motor_7">
      <hardwareInterface>PositionJointInterface</hardwareInterface>
      <mechanicalReduction>1</mechanicalReduction>
    </actuator>
  </transmission>

  <!-- ALLEGRO -->
  <!-- SOURCE:
  https://github.com/simlabrobotics/allegro_hand_ros_v4/blob/master/src/allegro_hand_description/urdf/allegro_hand_description_right.urdf -->
  <!-- ======================== BASE PARAMS ========================= -->
  <!-- ======================== FINGER PARAMS ======================== -->
  <!-- full height from joint to tip. when used,
    the radius of the finger tip sphere will be subtracted
    and one fixed link will be added for the tip. -->
  <!-- ========================= THUMB PARAMS ========================= -->
  <!-- ========================= LIMITS ========================= -->
  <!-- ============================================================================= -->
  <!-- PALM -->
  <link name="palm_link">
  </link>

  <!-- Keep palm_link with nothing so that its center of mass is at its origin, attach this
  palm_link_content for all inertial/collision/visual info -->
  <link name="palm_link_content">
    <visual>
      <geometry>
        <mesh filename="new_allegro_meshes/base_link.STL" />
      </geometry>
      <origin rpy="0 0 0" xyz="0 0 0 " />
      <material name="black">
        <color rgba="0.2 0.2 0.2 1" />
      </material>
    </visual>
    <collision>
      <origin rpy="0 0 0" xyz="-0.009300 0 -0.0475" />
      <geometry>
        <box size="0.0408 0.1130 0.095" />
      </geometry>
    </collision>
    <inertial>
      <origin rpy="0 0 0" xyz="0 0 0.0475" />
      <mass value="0.4154" />
      <inertia ixx="1e-4" ixy="0.0" ixz="0.0" iyy="1e-4" iyz="0.0" izz="1e-4" />
    </inertial>
  </link>

  <joint name="palm_link_joint_content" type="fixed">
    <parent link="palm_link" />
    <child link="palm_link_content" />
    <origin rpy="0 0 0" xyz="0 0 0" />
  </joint>

  <!--Sphere
  link-->
  <link name="palm_link_sphere2">
  </link>

  <joint name="palm_link_joint_sphere2" type="fixed">
    <parent link="palm_link" />
    <child link="palm_link_sphere2" />
    <origin rpy="0 0 0" xyz="-0.02 0.03 -0.03" />
    <axis xyz="0 0 1" />
  </joint>

  <link name="palm_link_sphere3">
  </link>

  <joint name="palm_link_joint_sphere3" type="fixed">
    <parent link="palm_link" />
    <child link="palm_link_sphere3" />
    <origin rpy="0 0 0" xyz="-0.02 -0.03 -0.03" />
    <axis xyz="0 0 1" />
  </joint>

  <link name="palm_link_sphere4">
  </link>

  <joint name="palm_link_joint_sphere4" type="fixed">
    <parent link="palm_link" />
    <child link="palm_link_sphere4" />
    <origin rpy="0 0 0" xyz="-0.02 0.03 -0.1" />
    <axis xyz="0 0 1" />
  </joint>

  <link name="palm_link_sphere5">
  </link>

  <joint name="palm_link_joint_sphere5" type="fixed">
    <parent link="palm_link" />
    <child link="palm_link_sphere5" />
    <origin rpy="0 0 0" xyz="-0.02 -0.03 -0.1" />
    <axis xyz="0 0 1" />
  </joint>

  <link name="palm_link_sphere6">
  </link>

  <joint name="palm_link_joint_sphere6" type="fixed">
    <parent link="palm_link" />
    <child link="palm_link_sphere6" />
    <origin rpy="0 0 0" xyz="-0.02 0.03 -0.17" />
    <axis xyz="0 0 1" />
  </joint>

  <link name="palm_link_sphere7">
  </link>

  <joint name="palm_link_joint_sphere7" type="fixed">
    <parent link="palm_link" />
    <child link="palm_link_sphere7" />
    <origin rpy="0 0 0" xyz="-0.02 -0.03 -0.17" />
    <axis xyz="0 0 1" />
  </joint>

  <link name="palm_link_sphere8">
  </link>

  <joint name="palm_link_joint_sphere8" type="fixed">
    <parent link="palm_link" />
    <child link="palm_link_sphere8" />
    <origin rpy="0 0 0" xyz="-0.02 -0.08 -0.12" />
    <axis xyz="0 0 1" />
  </joint>

  <link name="palm_link_sphere9">
  </link>

  <joint name="palm_link_joint_sphere9" type="fixed">
    <parent link="palm_link" />
    <child link="palm_link_sphere9" />
    <origin rpy="0 0 0" xyz="0.03 -0.08 -0.12" />
    <axis xyz="0 0 1" />
  </joint>

  <link name="palm_x">
    <inertial>
      <mass value="0.04" />
      <inertia ixx="5.1458e-5" ixy="0" ixz="0" iyy="5.1458e-5" iyz="0" izz="6.125e-5" />
    </inertial>
  </link>

  <link name="palm_x_neg">
    <inertial>
      <mass value="0.04" />
      <inertia ixx="5.1458e-5" ixy="0" ixz="0" iyy="5.1458e-5" iyz="0" izz="6.125e-5" />
    </inertial>
  </link>

  <link name="palm_y">
    <inertial>
      <mass value="0.04" />
      <inertia ixx="5.1458e-5" ixy="0" ixz="0" iyy="5.1458e-5" iyz="0" izz="6.125e-5" />
    </inertial>
  </link>

  <link name="palm_y_neg">
    <inertial>
      <mass value="0.04" />
      <inertia ixx="5.1458e-5" ixy="0" ixz="0" iyy="5.1458e-5" iyz="0" izz="6.125e-5" />
    </inertial>
  </link>

  <link name="palm_z">
    <inertial>
      <mass value="0.04" />
      <inertia ixx="5.1458e-5" ixy="0" ixz="0" iyy="5.1458e-5" iyz="0" izz="6.125e-5" />
    </inertial>
  </link>

  <link name="palm_z_neg">
    <inertial>
      <mass value="0.04" />
      <inertia ixx="5.1458e-5" ixy="0" ixz="0" iyy="5.1458e-5" iyz="0" izz="6.125e-5" />
    </inertial>
  </link>

  <!-- ============================================================================= -->
  <!-- FINGERS -->
  <!-- RIGHT HAND due to which finger is number 0 -->
  <!-- for LEFT HAND switch the sign of the **offset_origin_y** and **finger_angle_r** parameters-->
  <!-- [LINK 0, 4, 8] -->
  <link name="index_link_0">
    <visual>
      <geometry>
        <mesh filename="new_allegro_meshes/link_0.0.STL" />
      </geometry>
      <material name="black" />
    </visual>
    <collision>
      <geometry>
        <box size="0.0196 0.0275 0.0164" />
      </geometry>
      <origin rpy="0 0 0" xyz="0 0 0.0082" />
    </collision>
    <inertial>
      <mass value="0.0119" />
      <origin rpy="0 0 0" xyz="0 0 0" />
      <inertia ixx="1.01666658333e-06" ixy="0.0" ixz="0.0" iyy="6.47677333333e-07" iyz="0.0"
        izz="1.01666658333e-06" />
    </inertial>
  </link>
  <joint name="index_joint_0" type="revolute">
    <axis xyz="0 0 1" />
    <limit effort="15" lower="-0.47" upper="0.47" velocity="7" />
    <parent link="palm_link" />
    <child link="index_link_0" />
    <origin rpy="-0.08726646255 0 0" xyz="0 0.0435 -0.001542" />
    <dynamics damping="3" friction="10" />
  </joint>
  <!-- [LINK 1, 5, 9] -->
  <link name="index_link_1">
    <visual>
      <geometry>
        <mesh filename="new_allegro_meshes/link_1.0.STL" />
      </geometry>
      <material name="black" />
    </visual>
    <collision>
      <geometry>
        <box size="0.0196 0.0275 0.054" />
      </geometry>
      <origin rpy="0 0 0" xyz="0 0 0.027" />
    </collision>
    <inertial>
      <mass value="0.065" />
      <origin rpy="0 0 0" xyz="0 0 0" />
      <inertia ixx="7.95654166667e-05" ixy="1.7199e-05" ixz="8.75875e-06" iyy="2.47088833333e-05"
        iyz="2.413125e-05" izz="7.95654166667e-05" />
    </inertial>
  </link>
  <joint name="index_joint_1" type="revolute">
    <limit effort="15" lower="-0.196" upper="1.61" velocity="7" />
    <axis xyz="0 1 0" />
    <parent link="index_link_0" />
    <child link="index_link_1" />
    <origin xyz="0 0 0.0164" />
    <dynamics damping="3" friction="5" />
  </joint>
  <!-- [LINK 2, 6, 10]-->
  <link name="index_link_2">
    <visual>
      <geometry>
        <mesh filename="new_allegro_meshes/link_2.0.STL" />
      </geometry>
      <material name="black" />
    </visual>
    <collision>
      <geometry>
        <box size="0.0196 0.0275 0.0384" />
      </geometry>
      <origin rpy="0 0 0" xyz="0 0 0.0192" />
    </collision>
    <inertial>
      <mass value="0.0355" />
      <origin rpy="0 0 0" xyz="0 0 0" />
      <inertia ixx="2.63979183333e-05" ixy="6.67968e-06" ixz="4.783625e-06" iyy="1.34948516667e-05"
        iyz="9.372e-06" izz="2.63979183333e-05" />
    </inertial>
  </link>
  <joint name="index_joint_2" type="revolute">
    <axis xyz="0 1 0" />
    <limit effort="15" lower="-0.174" upper="1.709" velocity="7" />
    <parent link="index_link_1" />
    <child link="index_link_2" />
    <origin xyz="0 0 0.054" />
    <dynamics damping="8" friction="10" />
  </joint>
  <!-- [LINK 3, 7, 11] -->
  <link name="index_link_3">
    <visual>
      <geometry>
        <mesh filename="new_allegro_meshes/link_3.0.STL" />
      </geometry>
      <material name="black" />
    </visual>
    <collision>
      <geometry>
        <box size="0.0196 0.0275 0.0267" />
      </geometry>
      <origin rpy="0 0 0" xyz="0 0 0.01335" />
    </collision>
    <inertial>
      <mass value="0.0096" />
      <origin rpy="0 0 0" xyz="0 0 0" />
      <inertia ixx="4.701248e-06" ixy="1.255968e-06" ixz="1.2936e-06" iyy="3.649312e-06"
        iyz="1.7622e-06" izz="4.701248e-06" />
    </inertial>
  </link>
  <joint name="index_joint_3" type="revolute">
    <axis xyz="0 1 0" />
    <limit effort="15" lower="-0.227" upper="1.618" velocity="7" />
    <parent link="index_link_2" />
    <child link="index_link_3" />
    <origin xyz="0 0 0.0384" />
    <dynamics damping="10" friction="12" />
  </joint>
  <!-- [FINGER TIP] -->
  <link name="index_biotac_tip">
    <visual>
      <geometry>
        <mesh filename="new_allegro_meshes/link_3.0_tip.STL" />
      </geometry>
      <material name="white">
        <color rgba=".9 .9 .9 1" />
      </material>
    </visual>
    <collision>
      <geometry>
        <sphere radius="0.012" />
      </geometry>
    </collision>
    <inertial>
      <mass value="0.0168" />
      <origin rpy="0 0 0" xyz="0 0 0" />
      <inertia ixx="9.68e-07" ixy="0" ixz="0" iyy="9.68e-07" iyz="0" izz="9.68e-07" />
    </inertial>
  </link>
  <joint name="index_biotac_tip_joint" type="fixed">
    <parent link="index_link_3" />
    <child link="index_biotac_tip" />
    <origin rpy="0 0 0" xyz="0 0 0.0267" />
  </joint>
  <!-- [LINK 0, 4, 8] -->
  <link name="middle_link_0">
    <visual>
      <geometry>
        <mesh filename="new_allegro_meshes/link_0.0.STL" />
      </geometry>
      <material name="black" />
    </visual>
    <collision>
      <geometry>
        <box size="0.0196 0.0275 0.0164" />
      </geometry>
      <origin rpy="0 0 0" xyz="0 0 0.0082" />
    </collision>
    <inertial>
      <mass value="0.0119" />
      <origin rpy="0 0 0" xyz="0 0 0" />
      <inertia ixx="1.01666658333e-06" ixy="0.0" ixz="0.0" iyy="6.47677333333e-07" iyz="0.0"
        izz="1.01666658333e-06" />
    </inertial>
  </link>
  <joint name="middle_joint_0" type="revolute">
    <axis xyz="0 0 1" />
    <limit effort="15" lower="-0.47" upper="0.47" velocity="7" />
    <parent link="palm_link" />
    <child link="middle_link_0" />
    <origin rpy="0.0 0 0" xyz="0 0 0.0007" />
    <dynamics damping="3" friction="10" />
  </joint>
  <!-- [LINK 1, 5, 9] -->
  <link name="middle_link_1">
    <visual>
      <geometry>
        <mesh filename="new_allegro_meshes/link_1.0.STL" />
      </geometry>
      <material name="black" />
    </visual>
    <collision>
      <geometry>
        <box size="0.0196 0.0275 0.054" />
      </geometry>
      <origin rpy="0 0 0" xyz="0 0 0.027" />
    </collision>
    <inertial>
      <mass value="0.065" />
      <origin rpy="0 0 0" xyz="0 0 0" />
      <inertia ixx="7.95654166667e-05" ixy="1.7199e-05" ixz="8.75875e-06" iyy="2.47088833333e-05"
        iyz="2.413125e-05" izz="7.95654166667e-05" />
    </inertial>
  </link>
  <joint name="middle_joint_1" type="revolute">
    <limit effort="15" lower="-0.196" upper="1.61" velocity="7" />
    <axis xyz="0 1 0" />
    <parent link="middle_link_0" />
    <child link="middle_link_1" />
    <origin xyz="0 0 0.0164" />
    <dynamics damping="3" friction="5" />
  </joint>
  <!-- [LINK 2, 6, 10]-->
  <link name="middle_link_2">
    <visual>
      <geometry>
        <mesh filename="new_allegro_meshes/link_2.0.STL" />
      </geometry>
      <material name="black" />
    </visual>
    <collision>
      <geometry>
        <box size="0.0196 0.0275 0.0384" />
      </geometry>
      <origin rpy="0 0 0" xyz="0 0 0.0192" />
    </collision>
    <inertial>
      <mass value="0.0355" />
      <origin rpy="0 0 0" xyz="0 0 0" />
      <inertia ixx="2.63979183333e-05" ixy="6.67968e-06" ixz="4.783625e-06" iyy="1.34948516667e-05"
        iyz="9.372e-06" izz="2.63979183333e-05" />
    </inertial>
  </link>
  <joint name="middle_joint_2" type="revolute">
    <axis xyz="0 1 0" />
    <limit effort="15" lower="-0.174" upper="1.709" velocity="7" />
    <parent link="middle_link_1" />
    <child link="middle_link_2" />
    <origin xyz="0 0 0.054" />
    <dynamics damping="8" friction="10" />
  </joint>
  <!-- [LINK 3, 7, 11] -->
  <link name="middle_link_3">
    <visual>
      <geometry>
        <mesh filename="new_allegro_meshes/link_3.0.STL" />
      </geometry>
      <material name="black" />
    </visual>
    <collision>
      <geometry>
        <box size="0.0196 0.0275 0.0267" />
      </geometry>
      <origin rpy="0 0 0" xyz="0 0 0.01335" />
    </collision>
    <inertial>
      <mass value="0.0096" />
      <origin rpy="0 0 0" xyz="0 0 0" />
      <inertia ixx="4.701248e-06" ixy="1.255968e-06" ixz="1.2936e-06" iyy="3.649312e-06"
        iyz="1.7622e-06" izz="4.701248e-06" />
    </inertial>
  </link>
  <joint name="middle_joint_3" type="revolute">
    <axis xyz="0 1 0" />
    <limit effort="15" lower="-0.227" upper="1.618" velocity="7" />
    <parent link="middle_link_2" />
    <child link="middle_link_3" />
    <origin xyz="0 0 0.0384" />
    <dynamics damping="10" friction="12" />
  </joint>
  <!-- [FINGER TIP] -->
  <link name="middle_biotac_tip">
    <visual>
      <geometry>
        <mesh filename="new_allegro_meshes/link_3.0_tip.STL" />
      </geometry>
      <material name="white">
        <color rgba=".9 .9 .9 1" />
      </material>
    </visual>
    <collision>
      <geometry>
        <sphere radius="0.012" />
      </geometry>
    </collision>
    <inertial>
      <mass value="0.0168" />
      <origin rpy="0 0 0" xyz="0 0 0" />
      <inertia ixx="9.68e-07" ixy="0" ixz="0" iyy="9.68e-07" iyz="0" izz="9.68e-07" />
    </inertial>
  </link>
  <joint name="middle_biotac_tip_joint" type="fixed">
    <parent link="middle_link_3" />
    <child link="middle_biotac_tip" />
    <origin rpy="0 0 0" xyz="0 0 0.0267" />
  </joint>
  <!-- [LINK 0, 4, 8] -->
  <link name="ring_link_0">
    <visual>
      <geometry>
        <mesh filename="new_allegro_meshes/link_0.0.STL" />
      </geometry>
      <material name="black" />
    </visual>
    <collision>
      <geometry>
        <box size="0.0196 0.0275 0.0164" />
      </geometry>
      <origin rpy="0 0 0" xyz="0 0 0.0082" />
    </collision>
    <inertial>
      <mass value="0.0119" />
      <origin rpy="0 0 0" xyz="0 0 0" />
      <inertia ixx="1.01666658333e-06" ixy="0.0" ixz="0.0" iyy="6.47677333333e-07" iyz="0.0"
        izz="1.01666658333e-06" />
    </inertial>
  </link>
  <joint name="ring_joint_0" type="revolute">
    <axis xyz="0 0 1" />
    <limit effort="15" lower="-0.47" upper="0.47" velocity="7" />
    <parent link="palm_link" />
    <child link="ring_link_0" />
    <origin rpy="0.08726646255 0 0" xyz="0 -0.0435 -0.001542" />
    <dynamics damping="3" friction="10" />
  </joint>
  <!-- [LINK 1, 5, 9] -->
  <link name="ring_link_1">
    <visual>
      <geometry>
        <mesh filename="new_allegro_meshes/link_1.0.STL" />
      </geometry>
      <material name="black" />
    </visual>
    <collision>
      <geometry>
        <box size="0.0196 0.0275 0.054" />
      </geometry>
      <origin rpy="0 0 0" xyz="0 0 0.027" />
    </collision>
    <inertial>
      <mass value="0.065" />
      <origin rpy="0 0 0" xyz="0 0 0" />
      <inertia ixx="7.95654166667e-05" ixy="1.7199e-05" ixz="8.75875e-06" iyy="2.47088833333e-05"
        iyz="2.413125e-05" izz="7.95654166667e-05" />
    </inertial>
  </link>
  <joint name="ring_joint_1" type="revolute">
    <limit effort="15" lower="-0.196" upper="1.61" velocity="7" />
    <axis xyz="0 1 0" />
    <parent link="ring_link_0" />
    <child link="ring_link_1" />
    <origin xyz="0 0 0.0164" />
    <dynamics damping="3" friction="5" />
  </joint>
  <!-- [LINK 2, 6, 10]-->
  <link name="ring_link_2">
    <visual>
      <geometry>
        <mesh filename="new_allegro_meshes/link_2.0.STL" />
      </geometry>
      <material name="black" />
    </visual>
    <collision>
      <geometry>
        <box size="0.0196 0.0275 0.0384" />
      </geometry>
      <origin rpy="0 0 0" xyz="0 0 0.0192" />
    </collision>
    <inertial>
      <mass value="0.0355" />
      <origin rpy="0 0 0" xyz="0 0 0" />
      <inertia ixx="2.63979183333e-05" ixy="6.67968e-06" ixz="4.783625e-06" iyy="1.34948516667e-05"
        iyz="9.372e-06" izz="2.63979183333e-05" />
    </inertial>
  </link>
  <joint name="ring_joint_2" type="revolute">
    <axis xyz="0 1 0" />
    <limit effort="15" lower="-0.174" upper="1.709" velocity="7" />
    <parent link="ring_link_1" />
    <child link="ring_link_2" />
    <origin xyz="0 0 0.054" />
    <dynamics damping="8" friction="10" />
  </joint>
  <!-- [LINK 3, 7, 11] -->
  <link name="ring_link_3">
    <visual>
      <geometry>
        <mesh filename="new_allegro_meshes/link_3.0.STL" />
      </geometry>
      <material name="black" />
    </visual>
    <collision>
      <geometry>
        <box size="0.0196 0.0275 0.0267" />
      </geometry>
      <origin rpy="0 0 0" xyz="0 0 0.01335" />
    </collision>
    <inertial>
      <mass value="0.0096" />
      <origin rpy="0 0 0" xyz="0 0 0" />
      <inertia ixx="4.701248e-06" ixy="1.255968e-06" ixz="1.2936e-06" iyy="3.649312e-06"
        iyz="1.7622e-06" izz="4.701248e-06" />
    </inertial>
  </link>
  <joint name="ring_joint_3" type="revolute">
    <axis xyz="0 1 0" />
    <limit effort="15" lower="-0.227" upper="1.618" velocity="7" />
    <parent link="ring_link_2" />
    <child link="ring_link_3" />
    <origin xyz="0 0 0.0384" />
    <dynamics damping="10" friction="12" />
  </joint>
  <!-- [FINGER TIP] -->
  <link name="ring_biotac_tip">
    <visual>
      <geometry>
        <mesh filename="new_allegro_meshes/link_3.0_tip.STL" />
      </geometry>
      <material name="white">
        <color rgba=".9 .9 .9 1" />
      </material>
    </visual>
    <collision>
      <geometry>
        <sphere radius="0.012" />
      </geometry>
    </collision>
    <inertial>
      <mass value="0.0168" />
      <origin rpy="0 0 0" xyz="0 0 0" />
      <inertia ixx="9.68e-07" ixy="0" ixz="0" iyy="9.68e-07" iyz="0" izz="9.68e-07" />
    </inertial>
  </link>
  <joint name="ring_biotac_tip_joint" type="fixed">
    <parent link="ring_link_3" />
    <child link="ring_biotac_tip" />
    <origin rpy="0 0 0" xyz="0 0 0.0267" />
  </joint>
  <!-- THUMB -->
  <!-- [LINK 12] -->
  <link name="thumb_link_0">
    <visual>
      <geometry>
        <mesh filename="new_allegro_meshes/link_12.0_right.STL" />
      </geometry>
      <material name="black">
        <color rgba=".2 .2 .2 1" />
      </material>
      <origin rpy="3.1415926518 0 0" xyz="0 0 0" />
    </visual>
    <collision>
      <geometry>
        <box size="0.0358 0.034 0.0455" />
      </geometry>
      <origin rpy="0 0 0" xyz="-0.0179 0.009 0.0145" />
    </collision>
    <inertial>
      <mass value="0.0176" />
      <origin rpy="0 0 0" xyz="0 0 0" />
      <inertia ixx="1.89273333333e-5" ixy="7.16716e-06" ixz="5.35568e-06" iyy="1.43008213333e-05"
        iyz="6.8068e-06" izz="1.89273333333e-05" />
    </inertial>
  </link>
  <joint name="thumb_joint_0" type="revolute">
    <axis xyz="-1 0 0" />
    <limit effort="15" lower="0.263" upper="1.396" velocity="7" />
    <parent link="palm_link" />
    <child link="thumb_link_0" />
    <origin rpy="0 -1.65806278845 -1.5707963259" xyz="-0.0182 0.019333 -0.045987" />
    <dynamics damping="3" friction="10" />
  </joint>
  <!-- [LINK 13] -->
  <link name="thumb_link_1">
    <visual>
      <geometry>
        <mesh filename="new_allegro_meshes/link_13.0.STL" />
      </geometry>
      <material name="black">
        <color rgba=".2 .2 .2 1" />
      </material>
    </visual>
    <collision>
      <geometry>
        <box size="0.0196 0.0275 0.0177" />
      </geometry>
      <origin rpy="0 0 0" xyz="0 0 0.00885" />
    </collision>
    <inertial>
      <mass value="0.0119" />
      <origin rpy="0 0 0" xyz="0 0 0" />
      <inertia ixx="4.24250866667e-06" ixy="1.032087e-06" ixz="1.603525e-06" iyy="4.52362633333e-06"
        iyz="1.44808125e-06" izz="4.24250866667e-06" />
    </inertial>
  </link>
  <joint name="thumb_joint_1" type="revolute">
    <axis xyz="0 0 1" />
    <limit effort="15" lower="-0.105" upper="1.163" velocity="7" />
    <parent link="thumb_link_0" />
    <child link="thumb_link_1" />
    <origin xyz="-0.027 0.005 0.0399" />
    <dynamics damping="3" friction="5" />
  </joint>
  <!-- [LINK 14] -->
  <link name="thumb_link_2">
    <visual>
      <geometry>
        <mesh filename="new_allegro_meshes/link_14.0.STL" />
      </geometry>
      <material name="black">
      </material>
    </visual>
    <collision>
      <geometry>
        <box size="0.0196 0.0275 0.0514" />
      </geometry>
      <origin rpy="0 0 0" xyz="0 0 0.0257" />
    </collision>
    <inertial>
      <mass value="0.038" />
      <origin rpy="0 0 0" xyz="0 0 0" />
      <inertia ixx="4.30439933333e-05" ixy="9.57068e-06" ixz="5.1205e-06" iyy="1.44451933333e-05"
        iyz="1.342825e-05" izz="4.30439933333e-05" />
    </inertial>
  </link>
  <joint name="thumb_joint_2" type="revolute">
    <axis xyz="0 1 0" />
    <limit effort="15" lower="-0.189" upper="1.644" velocity="7" />
    <parent link="thumb_link_1" />
    <child link="thumb_link_2" />
    <origin xyz="0 0 0.0177" />
    <dynamics damping="3" friction="10" />
  </joint>
  <!-- [LINK 15] -->
  <link name="thumb_link_3">
    <visual>
      <geometry>
        <mesh filename="new_allegro_meshes/link_15.0.STL" />
      </geometry>
      <material name="black">
      </material>
    </visual>
    <collision>
      <geometry>
        <box size="0.0196 0.0275 0.0423" />
      </geometry>
      <origin rpy="0 0 0" xyz="0 0 0.02115" />
    </collision>
    <inertial>
      <mass value="0.0388" />
      <origin rpy="0 0 0" xyz="0 0 0" />
      <inertia ixx="3.29223173333e-05" ixy="8.042076e-06" ixz="5.2283e-06" iyy="1.47493026667e-5"
        iyz="1.1283525e-5" izz="3.29223173333e-05" />
    </inertial>
  </link>
  <joint name="thumb_joint_3" type="revolute">
    <axis xyz="0 1 0" />
    <limit effort="15" lower="-0.162" upper="1.719" velocity="7" />
    <parent link="thumb_link_2" />
    <child link="thumb_link_3" />
    <origin xyz="0 0 0.0514" />
    <dynamics damping="3" friction="12" />
  </joint>
  <!-- [FINGER TIP] -->
  <link name="thumb_biotac_tip">
    <visual>
      <geometry>
        <mesh filename="new_allegro_meshes/link_15.0_tip.STL" />
      </geometry>
      <material name="white">
        <color rgba=".9 .9 .9 1" />
      </material>
    </visual>
    <collision>
      <geometry>
        <sphere radius="0.012" />
      </geometry>
      <origin rpy="0 0 0" xyz="0 0 0" />
    </collision>
    <inertial>
      <mass value="0.0168" />
      <origin rpy="0 0 0" xyz="0 0 0" />
      <inertia ixx="9.68e-07" ixy="0" ixz="0" iyy="9.68e-07" iyz="0" izz="9.68e-07" />
    </inertial>
  </link>
  <joint name="thumb_biotac_tip_joint" type="fixed">
    <parent link="thumb_link_3" />
    <child link="thumb_biotac_tip" />
    <origin rpy="0 0 0" xyz="0 0 0.0423" />
  </joint>
  <!-- ============================================================================= -->
  <!-- THUMB MACRO -->
  <!-- END THUMB MACRO -->
  <!-- THREE FINGER MACRO -->
  <!-- [[END]] THREE FINGER MACRO -->

  <!-- Create a different *root* for the allegro hand -->
  <!-- Note: this offset is just eyeballed... -->
  <joint name="iiwa14_allegro" type="fixed">
    <parent link="iiwa14_link_ee" />
    <child link="palm_link" />
    <!--  From Claire -->
    <!-- <origin xyz="-0.14 0 0.035" rpy="0 -1.57 0" /> -->

    <origin xyz="-0.14 0 0.0325" rpy="0 -1.57 0" />
  </joint>

  <joint name="palm_x_joint" type="fixed">
    <origin rpy="0. 0. 0." xyz="0.25 0. 0." />
    <parent link="palm_link" />
    <child link="palm_x" />
  </joint>

  <joint name="palm_x_neg_joint" type="fixed">
    <origin rpy="0. 0. 0." xyz="-0.25 0. 0." />
    <parent link="palm_link" />
    <child link="palm_x_neg" />
  </joint>

  <joint name="palm_y_joint" type="fixed">
    <origin rpy="0. 0. 0." xyz="0. 0.25 0." />
    <parent link="palm_link" />
    <child link="palm_y" />
  </joint>

  <joint name="palm_y_neg_joint" type="fixed">
    <origin rpy="0. 0. 0." xyz="0. -0.25 0." />
    <parent link="palm_link" />
    <child link="palm_y_neg" />
  </joint>

  <joint name="palm_z_joint" type="fixed">
    <origin rpy="0. 0. 0." xyz="0. 0. 0.25" />
    <parent link="palm_link" />
    <child link="palm_z" />
  </joint>

  <joint name="palm_z_neg_joint" type="fixed">
    <origin rpy="0. 0. 0." xyz="0. 0. -0.25" />
    <parent link="palm_link" />
    <child link="palm_z_neg" />
  </joint>

  <!--Sphere
  link-->
  <link name="index_link_1_sphere2">
  </link>

  <joint name="index_link_1_joint_sphere2" type="fixed">
    <parent link="index_link_1" />
    <child link="index_link_1_sphere2" />
    <origin rpy="0 0 0" xyz="0.0 0.0 0.027" />
    <axis xyz="0 0 1" />
  </joint>

  <!--Sphere
  link-->
  <link name="index_link_2_sphere2">
  </link>

  <joint name="index_link_2_joint_sphere2" type="fixed">
    <parent link="index_link_2" />
    <child link="index_link_2_sphere2" />
    <origin rpy="0 0 0" xyz="0.0 0.0 0.027" />
    <axis xyz="0 0 1" />
  </joint>

  <!--Sphere
  link-->
  <link name="index_link_3_sphere2">
  </link>

  <joint name="index_link_3_joint_sphere2" type="fixed">
    <parent link="index_link_3" />
    <child link="index_link_3_sphere2" />
    <origin rpy="0 0 0" xyz="0.0 0.0 0.027" />
    <axis xyz="0 0 1" />
  </joint>

  <!--Sphere
  link-->
  <link name="middle_link_1_sphere2">
  </link>

  <joint name="middle_link_1_joint_sphere2" type="fixed">
    <parent link="middle_link_1" />
    <child link="middle_link_1_sphere2" />
    <origin rpy="0 0 0" xyz="0.0 0.0 0.027" />
    <axis xyz="0 0 1" />
  </joint>

  <!--Sphere
  link-->
  <link name="middle_link_2_sphere2">
  </link>

  <joint name="middle_link_2_joint_sphere2" type="fixed">
    <parent link="middle_link_2" />
    <child link="middle_link_2_sphere2" />
    <origin rpy="0 0 0" xyz="0.0 0.0 0.027" />
    <axis xyz="0 0 1" />
  </joint>

  <!--Sphere
  link-->
  <link name="middle_link_3_sphere2">
  </link>

  <joint name="middle_link_3_joint_sphere2" type="fixed">
    <parent link="middle_link_3" />
    <child link="middle_link_3_sphere2" />
    <origin rpy="0 0 0" xyz="0.0 0.0 0.027" />
    <axis xyz="0 0 1" />
  </joint>

  <!--Sphere
  link-->
  <link name="ring_link_1_sphere2">
  </link>

  <joint name="ring_link_1_joint_sphere2" type="fixed">
    <parent link="ring_link_1" />
    <child link="ring_link_1_sphere2" />
    <origin rpy="0 0 0" xyz="0.0 0.0 0.027" />
    <axis xyz="0 0 1" />
  </joint>

  <!--Sphere
  link-->
  <link name="ring_link_2_sphere2">
  </link>

  <joint name="ring_link_2_joint_sphere2" type="fixed">
    <parent link="ring_link_2" />
    <child link="ring_link_2_sphere2" />
    <origin rpy="0 0 0" xyz="0.0 0.0 0.027" />
    <axis xyz="0 0 1" />
  </joint>

  <!--Sphere
  link-->
  <link name="ring_link_3_sphere2">
  </link>

  <joint name="ring_link_3_joint_sphere2" type="fixed">
    <parent link="ring_link_3" />
    <child link="ring_link_3_sphere2" />
    <origin rpy="0 0 0" xyz="0.0 0.0 0.027" />
    <axis xyz="0 0 1" />
  </joint>

  <!--Sphere
  link-->
  <link name="thumb_link_2_sphere2">
  </link>

  <joint name="thumb_link_2_joint_sphere2" type="fixed">
    <parent link="thumb_link_2" />
    <child link="thumb_link_2_sphere2" />
    <origin rpy="0 0 0" xyz="0.0 0.0 0.025" />
    <axis xyz="0 0 1" />
  </joint>

  <!--Sphere
  link-->
  <link name="thumb_link_3_sphere2">
  </link>

  <joint name="thumb_link_3_joint_sphere2" type="fixed">
    <parent link="thumb_link_3" />
    <child link="thumb_link_3_sphere2" />
    <origin rpy="0 0 0" xyz="0.0 0.0 0.025" />
    <axis xyz="0 0 1" />
  </joint>

  <!--Sphere
  link-->
  <link name="thumb_link_3_sphere3">
  </link>

  <joint name="thumb_link_3_joint_sphere3" type="fixed">
    <parent link="thumb_link_3" />
    <child link="thumb_link_3_sphere3" />
    <origin rpy="0 0 0" xyz="0.0 0.0 0.055" />
    <axis xyz="0 0 1" />
  </joint>

</robot>